 python3 manage.py runserver
Watching for file changes with StatReloader
Exception in thread django-main-thread:
Traceback (most recent call last):
  File "/Library/Frameworks/Python.framework/Versions/3.13/lib/python3.13/site-packages/django/db/backends/postgresql/base.py", line 25, in <module>
    import psycopg as Database
ModuleNotFoundError: No module named 'psycopg'

During handling of the above exception, another exception occurred:

Traceback (most recent call last):
  File "/Library/Frameworks/Python.framework/Versions/3.13/lib/python3.13/site-packages/django/db/backends/postgresql/base.py", line 27, in <module>
    import psycopg2 as Database
ModuleNotFoundError: No module named 'psycopg2'

During handling of the above exception, another exception occurred:

Traceback (most recent call last):
  File "/Library/Frameworks/Python.framework/Versions/3.13/lib/python3.13/threading.py", line 1041, in _bootstrap_inner
    self.run()
    ~~~~~~~~^^
  File "/Library/Frameworks/Python.framework/Versions/3.13/lib/python3.13/threading.py", line 992, in run
    self._target(*self._args, **self._kwargs)
    ~~~~~~~~~~~~^^^^^^^^^^^^^^^^^^^^^^^^^^^^^
  File "/Library/Frameworks/Python.framework/Versions/3.13/lib/python3.13/site-packages/django/utils/autoreload.py", line 64, in wrapper
    fn(*args, **kwargs)
    ~~^^^^^^^^^^^^^^^^^
  File "/Library/Frameworks/Python.framework/Versions/3.13/lib/python3.13/site-packages/django/core/management/commands/runserver.py", line 124, in inner_run
    autoreload.raise_last_exception()
    ~~~~~~~~~~~~~~~~~~~~~~~~~~~~~~~^^
  File "/Library/Frameworks/Python.framework/Versions/3.13/lib/python3.13/site-packages/django/utils/autoreload.py", line 86, in raise_last_exception
    raise _exception[1]
  File "/Library/Frameworks/Python.framework/Versions/3.13/lib/python3.13/site-packages/django/core/management/__init__.py", line 394, in execute
    autoreload.check_errors(django.setup)()
    ~~~~~~~~~~~~~~~~~~~~~~~~~~~~~~~~~~~~~^^
  File "/Library/Frameworks/Python.framework/Versions/3.13/lib/python3.13/site-packages/django/utils/autoreload.py", line 64, in wrapper
    fn(*args, **kwargs)
    ~~^^^^^^^^^^^^^^^^^
  File "/Library/Frameworks/Python.framework/Versions/3.13/lib/python3.13/site-packages/django/__init__.py", line 24, in setup
    apps.populate(settings.INSTALLED_APPS)
    ~~~~~~~~~~~~~^^^^^^^^^^^^^^^^^^^^^^^^^
  File "/Library/Frameworks/Python.framework/Versions/3.13/lib/python3.13/site-packages/django/apps/registry.py", line 116, in populate
    app_config.import_models()
    ~~~~~~~~~~~~~~~~~~~~~~~~^^
  File "/Library/Frameworks/Python.framework/Versions/3.13/lib/python3.13/site-packages/django/apps/config.py", line 269, in import_models
    self.models_module = import_module(models_module_name)
                         ~~~~~~~~~~~~~^^^^^^^^^^^^^^^^^^^^
  File "/Library/Frameworks/Python.framework/Versions/3.13/lib/python3.13/importlib/__init__.py", line 88, in import_module
    return _bootstrap._gcd_import(name[level:], package, level)
           ~~~~~~~~~~~~~~~~~~~~~~^^^^^^^^^^^^^^^^^^^^^^^^^^^^^^
  File "<frozen importlib._bootstrap>", line 1387, in _gcd_import
  File "<frozen importlib._bootstrap>", line 1360, in _find_and_load
  File "<frozen importlib._bootstrap>", line 1331, in _find_and_load_unlocked
  File "<frozen importlib._bootstrap>", line 935, in _load_unlocked
  File "<frozen importlib._bootstrap_external>", line 1026, in exec_module
  File "<frozen importlib._bootstrap>", line 488, in _call_with_frames_removed
  File "/Library/Frameworks/Python.framework/Versions/3.13/lib/python3.13/site-packages/django/contrib/auth/models.py", line 5, in <module>
    from django.contrib.auth.base_user import AbstractBaseUser, BaseUserManager
  File "/Library/Frameworks/Python.framework/Versions/3.13/lib/python3.13/site-packages/django/contrib/auth/base_user.py", line 43, in <module>
    class AbstractBaseUser(models.Model):
    ...<123 lines>...
            )
  File "/Library/Frameworks/Python.framework/Versions/3.13/lib/python3.13/site-packages/django/db/models/base.py", line 145, in __new__
    new_class.add_to_class("_meta", Options(meta, app_label))
    ~~~~~~~~~~~~~~~~~~~~~~^^^^^^^^^^^^^^^^^^^^^^^^^^^^^^^^^^^
  File "/Library/Frameworks/Python.framework/Versions/3.13/lib/python3.13/site-packages/django/db/models/base.py", line 373, in add_to_class
    value.contribute_to_class(cls, name)
    ~~~~~~~~~~~~~~~~~~~~~~~~~^^^^^^^^^^^
  File "/Library/Frameworks/Python.framework/Versions/3.13/lib/python3.13/site-packages/django/db/models/options.py", line 238, in contribute_to_class
    self.db_table, connection.ops.max_name_length()
                   ^^^^^^^^^^^^^^
  File "/Library/Frameworks/Python.framework/Versions/3.13/lib/python3.13/site-packages/django/utils/connection.py", line 15, in __getattr__
    return getattr(self._connections[self._alias], item)
                   ~~~~~~~~~~~~~~~~~^^^^^^^^^^^^^
  File "/Library/Frameworks/Python.framework/Versions/3.13/lib/python3.13/site-packages/django/utils/connection.py", line 62, in __getitem__
    conn = self.create_connection(alias)
  File "/Library/Frameworks/Python.framework/Versions/3.13/lib/python3.13/site-packages/django/db/utils.py", line 193, in create_connection
    backend = load_backend(db["ENGINE"])
  File "/Library/Frameworks/Python.framework/Versions/3.13/lib/python3.13/site-packages/django/db/utils.py", line 113, in load_backend
    return import_module("%s.base" % backend_name)
  File "/Library/Frameworks/Python.framework/Versions/3.13/lib/python3.13/importlib/__init__.py", line 88, in import_module
    return _bootstrap._gcd_import(name[level:], package, level)
           ~~~~~~~~~~~~~~~~~~~~~~^^^^^^^^^^^^^^^^^^^^^^^^^^^^^^
  File "/Library/Frameworks/Python.framework/Versions/3.13/lib/python3.13/site-packages/django/db/backends/postgresql/base.py", line 29, in <module>
    raise ImproperlyConfigured("Error loading psycopg2 or psycopg module")
django.core.exceptions.ImproperlyConfigured: Error loading psycopg2 or psycopg module
